Workbook
Name \S: #REF!
Name _DAT1: #REF!
Name _DAT1: #REF!
Name _DAT10: #REF!
Name _DAT10: #REF!
Name _DAT11: #REF!
Name _DAT11: #REF!
Name _DAT12: #REF!
Name _DAT12: #REF!
Name _DAT13: #REF!
Name _DAT13: #REF!
Name _DAT2: #REF!
Name _DAT2: #REF!
Name _DAT3: #REF!
Name _DAT3: #REF!
Name _DAT4: #REF!
Name _DAT4: #REF!
Name _DAT5: #REF!
Name _DAT5: #REF!
Name _DAT6: #REF!
Name _DAT6: #REF!
Name _DAT7: #REF!
Name _DAT7: #REF!
Name _DAT8: #REF!
Name _DAT8: #REF!
Name _DAT9: #REF!
Name _DAT9: #REF!
Name BALDATA: #REF!
Name Date: [1]Results!$A$3
Name Days: [1]Results!$D$3
Name DRSDATA: #REF!
Name FERNDATA: #REF!
Name FRCDATA: #REF!
Name Import: #REF!
Name INPUT: #REF!
Name LPUDB: #REF!
Name MSCF_ADJ: #REF!
Name PIPEFLOW_IMPORT: #REF!
Name PRELWIRE: #REF!
Name SACSCOPS: #REF!
Name TEST0: #REF!
Name TEST0: #REF!
Name TESTHKEY: #REF!
Name TESTHKEY: #REF!
Name TESTKEYS: #REF!
Name TESTKEYS: #REF!
Name TESTVKEY: #REF!
Name TESTVKEY: #REF!
Name TIEOUT: #REF!
Name WIRE: #REF!

Sheet Physical - BBLS
A1: Product | B1: Open | C1: Receipt | D1: Prod / Cons | E1: Shipment | F1: Loss/Gain | G1: Own Cons | H1: Close | K1: =MID(A1,9,25) | L1: Open | M1: Receipt | N1: Prod / Cons | O1: Shipment | P1: Loss/Gain | Q1: Own Cons | R1: Close | U1: =MID(K1,9,25)
A2: 00110 - Ballast Water | B2: 5431 | D2: -3788 | H2: 1644 | J2: =CONCATENATE(0,LEFT(A2,5)) -> 000110 | K2: =MID(A2,9,25) -> Ballast Water | L2: =ROUND(B2/2,2) -> 2715.5 | M2: =ROUND(C2/2,2) -> 0 | N2: =ROUND(D2/2,2) -> -1894 | O2: =ROUND(E2/2,2) -> 0 | P2: =ROUND(F2/2,2) -> 0 | Q2: =ROUND(G2/2,2) -> 0 | R2: =ROUND(H2/2,2) -> 822 | T2: =CONCATENATE(0,LEFT(K2,5)) -> 0Balla | U2: =MID(K2,9,25) -> Water
A3: 00130 - JP-5 ANTIICANT | B3: 2061 | D3: -1 | H3: 2060 | J3: =CONCATENATE(0,LEFT(A3,5)) -> 000130 | K3: =MID(A3,9,25) -> JP-5 ANTIICANT | L3: =ROUND(B3/2,2) -> 1030.5 | M3: =ROUND(C3/2,2) -> 0 | N3: =ROUND(D3/2,2) -> -0.5 | O3: =ROUND(E3/2,2) -> 0 | P3: =ROUND(F3/2,2) -> 0 | Q3: =ROUND(G3/2,2) -> 0 | R3: =ROUND(H3/2,2) -> 1030 | T3: =CONCATENATE(0,LEFT(K3,5)) -> 0JP-5 | U3: =MID(K3,9,25) -> IICANT
A4: 00204 - Napo | C4: 325074 | D4: -325074 | J4: =CONCATENATE(0,LEFT(A4,5)) -> 000204 | K4: =MID(A4,9,25) -> Napo | L4: =ROUND(B4/2,2) -> 0 | M4: =ROUND(C4/2,2) -> 162537 | N4: =ROUND(D4/2,2) -> -162537 | O4: =ROUND(E4/2,2) -> 0 | P4: =ROUND(F4/2,2) -> 0 | Q4: =ROUND(G4/2,2) -> 0 | R4: =ROUND(H4/2,2) -> 0 | T4: =CONCATENATE(0,LEFT(K4,5)) -> 0Napo | U4: =MID(K4,9,25)
A5: 00206 - Hoops | C5: 199292 | D5: -173752 | H5: 25539 | J5: =CONCATENATE(0,LEFT(A5,5)) -> 000206 | K5: =MID(A5,9,25) -> Hoops | L5: =ROUND(B5/2,2) -> 0 | M5: =ROUND(C5/2,2) -> 99646 | N5: =ROUND(D5/2,2) -> -86876 | O5: =ROUND(E5/2,2) -> 0 | P5: =ROUND(F5/2,2) -> 0 | Q5: =ROUND(G5/2,2) -> 0 | R5: =ROUND(H5/2,2) -> 12769.5 | T5: =CONCATENATE(0,LEFT(K5,5)) -> 0Hoops | U5: =MID(K5,9,25)
A6: 00215 - Cold Lake Blend Crude (Canada) | B6: 115840 | C6: 119656 | D6: -97251 | H6: 138245 | J6: =CONCATENATE(0,LEFT(A6,5)) -> 000215 | K6: =MID(A6,9,25) -> Cold Lake Blend Crude (Ca | L6: =ROUND(B6/2,2) -> 57920 | M6: =ROUND(C6/2,2) -> 59828 | N6: =ROUND(D6/2,2) -> -48625.5 | O6: =ROUND(E6/2,2) -> 0 | P6: =ROUND(F6/2,2) -> 0 | Q6: =ROUND(G6/2,2) -> 0 | R6: =ROUND(H6/2,2) -> 69122.5 | T6: =CONCATENATE(0,LEFT(K6,5)) -> 0Cold | U6: =MID(K6,9,25) -> e Blend Crude (Ca
A7: 00252 - Mars Crude | B7: 178261 | C7: -154 | D7: -178107 | J7: =CONCATENATE(0,LEFT(A7,5)) -> 000252 | K7: =MID(A7,9,25) -> Mars Crude | L7: =ROUND(B7/2,2) -> 89130.5 | M7: =ROUND(C7/2,2) -> -77 | N7: =ROUND(D7/2,2) -> -89053.5 | O7: =ROUND(E7/2,2) -> 0 | P7: =ROUND(F7/2,2) -> 0 | Q7: =ROUND(G7/2,2) -> 0 | R7: =ROUND(H7/2,2) -> 0 | T7: =CONCATENATE(0,LEFT(K7,5)) -> 0Mars | U7: =MID(K7,9,25) -> de
A8: 00280 - Maya | B8: 1531533 | C8: 6909043 | D8: -6882732 | F8: 3156 | H8: 1554688 | J8: =CONCATENATE(0,LEFT(A8,5)) -> 000280 | K8: =MID(A8,9,25) -> Maya | L8: =ROUND(B8/2,2) -> 765766.5 | M8: =ROUND(C8/2,2) -> 3454521.5 | N8: =ROUND(D8/2,2) -> -3441366 | O8: =ROUND(E8/2,2) -> 0 | P8: =ROUND(F8/2,2) -> 1578 | Q8: =ROUND(G8/2,2) -> 0 | R8: =ROUND(H8/2,2) -> 777344 | T8: =CONCATENATE(0,LEFT(K8,5)) -> 0Maya | U8: =MID(K8,9,25)
A9: 00306 - Toluene for gasoline blending | B9: 14994 | D9: 132501 | E9: 99637 | F9: 256 | H9: 47601 | J9: =CONCATENATE(0,LEFT(A9,5)) -> 000306 | K9: =MID(A9,9,25) -> Toluene for gasoline blen | L9: =ROUND(B9/2,2) -> 7497 | M9: =ROUND(C9/2,2) -> 0 | N9: =ROUND(D9/2,2) -> 66250.5 | O9: =ROUND(E9/2,2) -> 49818.5 | P9: =ROUND(F9/2,2) -> 128 | Q9: =ROUND(G9/2,2) -> 0 | R9: =ROUND(H9/2,2) -> 23800.5 | T9: =CONCATENATE(0,LEFT(K9,5)) -> 0Tolue | U9: =MID(K9,9,25) -> for gasoline blen
A10: 00319 - PUL 93 RVP 7/8# | B10: 700 | H10: 700 | J10: =CONCATENATE(0,LEFT(A10,5)) -> 000319 | K10: =MID(A10,9,25) -> PUL 93 RVP 7/8# | L10: =ROUND(B10/2,2) -> 350 | M10: =ROUND(C10/2,2) -> 0 | N10: =ROUND(D10/2,2) -> 0 | O10: =ROUND(E10/2,2) -> 0 | P10: =ROUND(F10/2,2) -> 0 | Q10: =ROUND(G10/2,2) -> 0 | R10: =ROUND(H10/2,2) -> 350 | T10: =CONCATENATE(0,LEFT(K10,5)) -> 0PUL 9 | U10: =MID(K10,9,25) -> VP 7/8#
A11: 00351 - RUL87 RVP 9.0 | B11: 57340 | C11: 175000 | D11: 1168033 | E11: 1128300 | F11: 1910 | H11: 270162 | J11: =CONCATENATE(0,LEFT(A11,5)) -> 000351 | K11: =MID(A11,9,25) -> RUL87 RVP 9.0 | L11: =ROUND(B11/2,2) -> 28670 | M11: =ROUND(C11/2,2) -> 87500 | N11: =ROUND(D11/2,2) -> 584016.5 | O11: =ROUND(E11/2,2) -> 564150 | P11: =ROUND(F11/2,2) -> 955 | Q11: =ROUND(G11/2,2) -> 0 | R11: =ROUND(H11/2,2) -> 135081 | T11: =CONCATENATE(0,LEFT(K11,5)) -> 0RUL87 | U11: =MID(K11,9,25) -> P 9.0
A12: 00402 - JP-8 ANTIICANT | B12: 77 | H12: 77 | J12: =CONCATENATE(0,LEFT(A12,5)) -> 000402 | K12: =MID(A12,9,25) -> JP-8 ANTIICANT | L12: =ROUND(B12/2,2) -> 38.5 | M12: =ROUND(C12/2,2) -> 0 | N12: =ROUND(D12/2,2) -> 0 | O12: =ROUND(E12/2,2) -> 0 | P12: =ROUND(F12/2,2) -> 0 | Q12: =ROUND(G12/2,2) -> 0 | R12: =ROUND(H12/2,2) -> 38.5 | T12: =CONCATENATE(0,LEFT(K12,5)) -> 0JP-8 | U12: =MID(K12,9,25) -> IICANT
A13: 00410 - JET A | C13: 258562 | D13: -155182 | E13: 103380 | J13: =CONCATENATE(0,LEFT(A13,5)) -> 000410 | K13: =MID(A13,9,25) -> JET A | L13: =ROUND(B13/2,2) -> 0 | M13: =ROUND(C13/2,2) -> 129281 | N13: =ROUND(D13/2,2) -> -77591 | O13: =ROUND(E13/2,2) -> 51690 | P13: =ROUND(F13/2,2) -> 0 | Q13: =ROUND(G13/2,2) -> 0 | R13: =ROUND(H13/2,2) -> 0 | T13: =CONCATENATE(0,LEFT(K13,5)) -> 0JET A | U13: =MID(K13,9,25)
A14: 00429 - Low Sulfur Diesel | D14: 39621 | E14: 39621 | J14: =CONCATENATE(0,LEFT(A14,5)) -> 000429 | K14: =MID(A14,9,25) -> Low Sulfur Diesel | L14: =ROUND(B14/2,2) -> 0 | M14: =ROUND(C14/2,2) -> 0 | N14: =ROUND(D14/2,2) -> 19810.5 | O14: =ROUND(E14/2,2) -> 19810.5 | P14: =ROUND(F14/2,2) -> 0 | Q14: =ROUND(G14/2,2) -> 0 | R14: =ROUND(H14/2,2) -> 0 | T14: =CONCATENATE(0,LEFT(K14,5)) -> 0Low S | U14: =MID(K14,9,25) -> ur Diesel
A15: 00646 - JP8 Turbine Fuel | D15: 397352 | E15: 295368 | F15: 230 | H15: 101754 | J15: =CONCATENATE(0,LEFT(A15,5)) -> 000646 | K15: =MID(A15,9,25) -> JP8 Turbine Fuel | L15: =ROUND(B15/2,2) -> 0 | M15: =ROUND(C15/2,2) -> 0 | N15: =ROUND(D15/2,2) -> 198676 | O15: =ROUND(E15/2,2) -> 147684 | P15: =ROUND(F15/2,2) -> 115 | Q15: =ROUND(G15/2,2) -> 0 | R15: =ROUND(H15/2,2) -> 50877 | T15: =CONCATENATE(0,LEFT(K15,5)) -> 0JP8 T | U15: =MID(K15,9,25) -> ine Fuel
A16: 00804 - Slop Oil | B16: 39364 | D16: 1584 | H16: 40948 | J16: =CONCATENATE(0,LEFT(A16,5)) -> 000804 | K16: =MID(A16,9,25) -> Slop Oil | L16: =ROUND(B16/2,2) -> 19682 | M16: =ROUND(C16/2,2) -> 0 | N16: =ROUND(D16/2,2) -> 792 | O16: =ROUND(E16/2,2) -> 0 | P16: =ROUND(F16/2,2) -> 0 | Q16: =ROUND(G16/2,2) -> 0 | R16: =ROUND(H16/2,2) -> 20474 | T16: =CONCATENATE(0,LEFT(K16,5)) -> 0Slop | U16: =MID(K16,9,25)
A17: 00863 - Purchased Hydrogen | C17: 79544 | D17: -79544 | J17: =CONCATENATE(0,LEFT(A17,5)) -> 000863 | K17: =MID(A17,9,25) -> Purchased Hydrogen | L17: =ROUND(B17/2,2) -> 0 | M17: =ROUND(C17/2,2) -> 39772 | N17: =ROUND(D17/2,2) -> -39772 | O17: =ROUND(E17/2,2) -> 0 | P17: =ROUND(F17/2,2) -> 0 | Q17: =ROUND(G17/2,2) -> 0 | R17: =ROUND(H17/2,2) -> 0 | T17: =CONCATENATE(0,LEFT(K17,5)) -> 0Purch | U17: =MID(K17,9,25) -> d Hydrogen
A18: 00866 - Coke Offsite | B18: 1451827 | D18: 755987 | E18: 1356645 | F18: 22679 | H18: 828490 | J18: =CONCATENATE(0,LEFT(A18,5)) -> 000866 | K18: =MID(A18,9,25) -> Coke Offsite | L18: =ROUND(B18/2,2) -> 725913.5 | M18: =ROUND(C18/2,2) -> 0 | N18: =ROUND(D18/2,2) -> 377993.5 | O18: =ROUND(E18/2,2) -> 678322.5 | P18: =ROUND(F18/2,2) -> 11339.5 | Q18: =ROUND(G18/2,2) -> 0 | R18: =ROUND(H18/2,2) -> 414245 | T18: =CONCATENATE(0,LEFT(K18,5)) -> 0Coke | U18: =MID(K18,9,25) -> site
A19: 00896 - Shell Marine Diesel Fuel | B19: 6178 | D19: 8660 | H19: 14838 | J19: =CONCATENATE(0,LEFT(A19,5)) -> 000896 | K19: =MID(A19,9,25) -> Shell Marine Diesel Fuel | L19: =ROUND(B19/2,2) -> 3089 | M19: =ROUND(C19/2,2) -> 0 | N19: =ROUND(D19/2,2) -> 4330 | O19: =ROUND(E19/2,2) -> 0 | P19: =ROUND(F19/2,2) -> 0 | Q19: =ROUND(G19/2,2) -> 0 | R19: =ROUND(H19/2,2) -> 7419 | T19: =CONCATENATE(0,LEFT(K19,5)) -> 0Shell | U19: =MID(K19,9,25) -> rine Diesel Fuel
A20: 00918 - PLAT-2 Feed | B20: 46609 | D20: 31653 | H20: 78262 | J20: =CONCATENATE(0,LEFT(A20,5)) -> 000918 | K20: =MID(A20,9,25) -> PLAT-2 Feed | L20: =ROUND(B20/2,2) -> 23304.5 | M20: =ROUND(C20/2,2) -> 0 | N20: =ROUND(D20/2,2) -> 15826.5 | O20: =ROUND(E20/2,2) -> 0 | P20: =ROUND(F20/2,2) -> 0 | Q20: =ROUND(G20/2,2) -> 0 | R20: =ROUND(H20/2,2) -> 39131 | T20: =CONCATENATE(0,LEFT(K20,5)) -> 0PLAT- | U20: =MID(K20,9,25) -> eed
A21: 01037 - Cat Crk Coke | D21: 77380 | G21: 77380 | J21: =CONCATENATE(0,LEFT(A21,5)) -> 001037 | K21: =MID(A21,9,25) -> Cat Crk Coke | L21: =ROUND(B21/2,2) -> 0 | M21: =ROUND(C21/2,2) -> 0 | N21: =ROUND(D21/2,2) -> 38690 | O21: =ROUND(E21/2,2) -> 0 | P21: =ROUND(F21/2,2) -> 0 | Q21: =ROUND(G21/2,2) -> 38690 | R21: =ROUND(H21/2,2) -> 0 | T21: =CONCATENATE(0,LEFT(K21,5)) -> 0Cat C | U21: =MID(K21,9,25) -> Coke
A22: 01046 - Shell Sulfur | B22: 45429 | D22: 84196 | E22: 71198 | H22: 58427 | J22: =CONCATENATE(0,LEFT(A22,5)) -> 001046 | K22: =MID(A22,9,25) -> Shell Sulfur | L22: =ROUND(B22/2,2) -> 22714.5 | M22: =ROUND(C22/2,2) -> 0 | N22: =ROUND(D22/2,2) -> 42098 | O22: =ROUND(E22/2,2) -> 35599 | P22: =ROUND(F22/2,2) -> 0 | Q22: =ROUND(G22/2,2) -> 0 | R22: =ROUND(H22/2,2) -> 29213.5 | T22: =CONCATENATE(0,LEFT(K22,5)) -> 0Shell | U22: =MID(K22,9,25) -> lfur
A23: 01048 - Carbon Dioxide | D23: 61999 | E23: 61999 | J23: =CONCATENATE(0,LEFT(A23,5)) -> 001048 | K23: =MID(A23,9,25) -> Carbon Dioxide | L23: =ROUND(B23/2,2) -> 0 | M23: =ROUND(C23/2,2) -> 0 | N23: =ROUND(D23/2,2) -> 30999.5 | O23: =ROUND(E23/2,2) -> 30999.5 | P23: =ROUND(F23/2,2) -> 0 | Q23: =ROUND(G23/2,2) -> 0 | R23: =ROUND(H23/2,2) -> 0 | T23: =CONCATENATE(0,LEFT(K23,5)) -> 0Carbo | U23: =MID(K23,9,25) -> ioxide
A24: 03300 - Transmix to Colex | B24: 930 | D24: 66 | H24: 997 | J24: =CONCATENATE(0,LEFT(A24,5)) -> 003300 | K24: =MID(A24,9,25) -> Transmix to Colex | L24: =ROUND(B24/2,2) -> 465 | M24: =ROUND(C24/2,2) -> 0 | N24: =ROUND(D24/2,2) -> 33 | O24: =ROUND(E24/2,2) -> 0 | P24: =ROUND(F24/2,2) -> 0 | Q24: =ROUND(G24/2,2) -> 0 | R24: =ROUND(H24/2,2) -> 498.5 | T24: =CONCATENATE(0,LEFT(K24,5)) -> 0Trans | U24: =MID(K24,9,25) -> to Colex
A25: 06819 - Methanol | B25: 12344 | D25: 25 | H25: 12369 | J25: =CONCATENATE(0,LEFT(A25,5)) -> 006819 | K25: =MID(A25,9,25) -> Methanol | L25: =ROUND(B25/2,2) -> 6172 | M25: =ROUND(C25/2,2) -> 0 | N25: =ROUND(D25/2,2) -> 12.5 | O25: =ROUND(E25/2,2) -> 0 | P25: =ROUND(F25/2,2) -> 0 | Q25: =ROUND(G25/2,2) -> 0 | R25: =ROUND(H25/2,2) -> 6184.5 | T25: =CONCATENATE(0,LEFT(K25,5)) -> 0Metha | U25: =MID(K25,9,25)
A26: 08021 - HDU-2 Feed | B26: 43130 | D26: -479 | H26: 42652 | J26: =CONCATENATE(0,LEFT(A26,5)) -> 008021 | K26: =MID(A26,9,25) -> HDU-2 Feed | L26: =ROUND(B26/2,2) -> 21565 | M26: =ROUND(C26/2,2) -> 0 | N26: =ROUND(D26/2,2) -> -239.5 | O26: =ROUND(E26/2,2) -> 0 | P26: =ROUND(F26/2,2) -> 0 | Q26: =ROUND(G26/2,2) -> 0 | R26: =ROUND(H26/2,2) -> 21326 | T26: =CONCATENATE(0,LEFT(K26,5)) -> 0HDU-2 | U26: =MID(K26,9,25) -> ed
A27: 08030 - HVY Raffinate | B27: 69160 | D27: -30422 | H27: 38738 | J27: =CONCATENATE(0,LEFT(A27,5)) -> 008030 | K27: =MID(A27,9,25) -> HVY Raffinate | L27: =ROUND(B27/2,2) -> 34580 | M27: =ROUND(C27/2,2) -> 0 | N27: =ROUND(D27/2,2) -> -15211 | O27: =ROUND(E27/2,2) -> 0 | P27: =ROUND(F27/2,2) -> 0 | Q27: =ROUND(G27/2,2) -> 0 | R27: =ROUND(H27/2,2) -> 19369 | T27: =CONCATENATE(0,LEFT(K27,5)) -> 0HVY R | U27: =MID(K27,9,25) -> inate
A28: 08048 - Light Cat Cracked Gasoline | D28: 53008 | E28: 53008 | J28: =CONCATENATE(0,LEFT(A28,5)) -> 008048 | K28: =MID(A28,9,25) -> Light Cat Cracked Gasolin | L28: =ROUND(B28/2,2) -> 0 | M28: =ROUND(C28/2,2) -> 0 | N28: =ROUND(D28/2,2) -> 26504 | O28: =ROUND(E28/2,2) -> 26504 | P28: =ROUND(F28/2,2) -> 0 | Q28: =ROUND(G28/2,2) -> 0 | R28: =ROUND(H28/2,2) -> 0 | T28: =CONCATENATE(0,LEFT(K28,5)) -> 0Light | U28: =MID(K28,9,25) -> t Cracked Gasolin
A29: 08060 - Motor Alkylate | B29: 85994 | D29: 35314 | H29: 121308 | J29: =CONCATENATE(0,LEFT(A29,5)) -> 008060 | K29: =MID(A29,9,25) -> Motor Alkylate | L29: =ROUND(B29/2,2) -> 42997 | M29: =ROUND(C29/2,2) -> 0 | N29: =ROUND(D29/2,2) -> 17657 | O29: =ROUND(E29/2,2) -> 0 | P29: =ROUND(F29/2,2) -> 0 | Q29: =ROUND(G29/2,2) -> 0 | R29: =ROUND(H29/2,2) -> 60654 | T29: =CONCATENATE(0,LEFT(K29,5)) -> 0Motor | U29: =MID(K29,9,25) -> kylate
A30: 08088 - MTBE | B30: 432 | H30: 432 | J30: =CONCATENATE(0,LEFT(A30,5)) -> 008088 | K30: =MID(A30,9,25) -> MTBE | L30: =ROUND(B30/2,2) -> 216 | M30: =ROUND(C30/2,2) -> 0 | N30: =ROUND(D30/2,2) -> 0 | O30: =ROUND(E30/2,2) -> 0 | P30: =ROUND(F30/2,2) -> 0 | Q30: =ROUND(G30/2,2) -> 0 | R30: =ROUND(H30/2,2) -> 216 | T30: =CONCATENATE(0,LEFT(K30,5)) -> 0MTBE | U30: =MID(K30,9,25)
A31: 08113 - Untreated Heavy Gas Oil | B31: 241656 | D31: -44193 | H31: 197463 | J31: =CONCATENATE(0,LEFT(A31,5)) -> 008113 | K31: =MID(A31,9,25) -> Untreated Heavy Gas Oil | L31: =ROUND(B31/2,2) -> 120828 | M31: =ROUND(C31/2,2) -> 0 | N31: =ROUND(D31/2,2) -> -22096.5 | O31: =ROUND(E31/2,2) -> 0 | P31: =ROUND(F31/2,2) -> 0 | Q31: =ROUND(G31/2,2) -> 0 | R31: =ROUND(H31/2,2) -> 98731.5 | T31: =CONCATENATE(0,LEFT(K31,5)) -> 0Untre | U31: =MID(K31,9,25) -> d Heavy Gas Oil
A32: 08152 - Untreated Cat Gasoline (off spec) | B32: 26853 | D32: 31287 | H32: 58139 | J32: =CONCATENATE(0,LEFT(A32,5)) -> 008152 | K32: =MID(A32,9,25) -> Untreated Cat Gasoline (o | L32: =ROUND(B32/2,2) -> 13426.5 | M32: =ROUND(C32/2,2) -> 0 | N32: =ROUND(D32/2,2) -> 15643.5 | O32: =ROUND(E32/2,2) -> 0 | P32: =ROUND(F32/2,2) -> 0 | Q32: =ROUND(G32/2,2) -> 0 | R32: =ROUND(H32/2,2) -> 29069.5 | T32: =CONCATENATE(0,LEFT(K32,5)) -> 0Untre | U32: =MID(K32,9,25) -> d Cat Gasoline (o
A33: 08160 - Off Spec Butane/Butylenes | B33: 10302 | D33: -818 | H33: 9484 | J33: =CONCATENATE(0,LEFT(A33,5)) -> 008160 | K33: =MID(A33,9,25) -> Off Spec Butane/Butylenes | L33: =ROUND(B33/2,2) -> 5151 | M33: =ROUND(C33/2,2) -> 0 | N33: =ROUND(D33/2,2) -> -409 | O33: =ROUND(E33/2,2) -> 0 | P33: =ROUND(F33/2,2) -> 0 | Q33: =ROUND(G33/2,2) -> 0 | R33: =ROUND(H33/2,2) -> 4742 | T33: =CONCATENATE(0,LEFT(K33,5)) -> 0Off S | U33: =MID(K33,9,25) -> Butane/Butylenes
A34: 08162 - Butane/Butylenes | B34: 13566 | C34: 77791 | D34: -79434 | H34: 11923 | J34: =CONCATENATE(0,LEFT(A34,5)) -> 008162 | K34: =MID(A34,9,25) -> Butane/Butylenes | L34: =ROUND(B34/2,2) -> 6783 | M34: =ROUND(C34/2,2) -> 38895.5 | N34: =ROUND(D34/2,2) -> -39717 | O34: =ROUND(E34/2,2) -> 0 | P34: =ROUND(F34/2,2) -> 0 | Q34: =ROUND(G34/2,2) -> 0 | R34: =ROUND(H34/2,2) -> 5961.5 | T34: =CONCATENATE(0,LEFT(K34,5)) -> 0Butan | U34: =MID(K34,9,25) -> utylenes
A35: 08200 - SGP Debut Bottoms | B35: 25995 | D35: -9321 | H35: 16674 | J35: =CONCATENATE(0,LEFT(A35,5)) -> 008200 | K35: =MID(A35,9,25) -> SGP Debut Bottoms | L35: =ROUND(B35/2,2) -> 12997.5 | M35: =ROUND(C35/2,2) -> 0 | N35: =ROUND(D35/2,2) -> -4660.5 | O35: =ROUND(E35/2,2) -> 0 | P35: =ROUND(F35/2,2) -> 0 | Q35: =ROUND(G35/2,2) -> 0 | R35: =ROUND(H35/2,2) -> 8337 | T35: =CONCATENATE(0,LEFT(K35,5)) -> 0SGP D | U35: =MID(K35,9,25) -> t Bottoms
A36: 08240 - Untreated Jet Fuel | B36: 74094 | D36: 9156 | H36: 83250 | J36: =CONCATENATE(0,LEFT(A36,5)) -> 008240 | K36: =MID(A36,9,25) -> Untreated Jet Fuel | L36: =ROUND(B36/2,2) -> 37047 | M36: =ROUND(C36/2,2) -> 0 | N36: =ROUND(D36/2,2) -> 4578 | O36: =ROUND(E36/2,2) -> 0 | P36: =ROUND(F36/2,2) -> 0 | Q36: =ROUND(G36/2,2) -> 0 | R36: =ROUND(H36/2,2) -> 41625 | T36: =CONCATENATE(0,LEFT(K36,5)) -> 0Untre | U36: =MID(K36,9,25) -> d Jet Fuel
A37: 08605 - SR C5/C6 | B37: 18484 | D37: 19931 | H37: 38414 | J37: =CONCATENATE(0,LEFT(A37,5)) -> 008605 | K37: =MID(A37,9,25) -> SR C5/C6 | L37: =ROUND(B37/2,2) -> 9242 | M37: =ROUND(C37/2,2) -> 0 | N37: =ROUND(D37/2,2) -> 9965.5 | O37: =ROUND(E37/2,2) -> 0 | P37: =ROUND(F37/2,2) -> 0 | Q37: =ROUND(G37/2,2) -> 0 | R37: =ROUND(H37/2,2) -> 19207 | T37: =CONCATENATE(0,LEFT(K37,5)) -> 0SR C5 | U37: =MID(K37,9,25)
A38: 08679 - Off Spec Naphtha | B38: 172845 | D38: -62647 | H38: 110197 | J38: =CONCATENATE(0,LEFT(A38,5)) -> 008679 | K38: =MID(A38,9,25) -> Off Spec Naphtha | L38: =ROUND(B38/2,2) -> 86422.5 | M38: =ROUND(C38/2,2) -> 0 | N38: =ROUND(D38/2,2) -> -31323.5 | O38: =ROUND(E38/2,2) -> 0 | P38: =ROUND(F38/2,2) -> 0 | Q38: =ROUND(G38/2,2) -> 0 | R38: =ROUND(H38/2,2) -> 55098.5 | T38: =CONCATENATE(0,LEFT(K38,5)) -> 0Off S | U38: =MID(K38,9,25) -> Naphtha
A39: 08708 - Cat Cracked Clarified Oil | B39: 88302 | D39: 104172 | E39: 143473 | H39: 49000 | J39: =CONCATENATE(0,LEFT(A39,5)) -> 008708 | K39: =MID(A39,9,25) -> Cat Cracked Clarified Oil | L39: =ROUND(B39/2,2) -> 44151 | M39: =ROUND(C39/2,2) -> 0 | N39: =ROUND(D39/2,2) -> 52086 | O39: =ROUND(E39/2,2) -> 71736.5 | P39: =ROUND(F39/2,2) -> 0 | Q39: =ROUND(G39/2,2) -> 0 | R39: =ROUND(H39/2,2) -> 24500 | T39: =CONCATENATE(0,LEFT(K39,5)) -> 0Cat C | U39: =MID(K39,9,25) -> ked Clarified Oil
A40: 08709 - Untreated Light CC Gas Oil | B40: 191156 | D40: -3821 | H40: 187336 | J40: =CONCATENATE(0,LEFT(A40,5)) -> 008709 | K40: =MID(A40,9,25) -> Untreated Light CC Gas Oi | L40: =ROUND(B40/2,2) -> 95578 | M40: =ROUND(C40/2,2) -> 0 | N40: =ROUND(D40/2,2) -> -1910.5 | O40: =ROUND(E40/2,2) -> 0 | P40: =ROUND(F40/2,2) -> 0 | Q40: =ROUND(G40/2,2) -> 0 | R40: =ROUND(H40/2,2) -> 93668 | T40: =CONCATENATE(0,LEFT(K40,5)) -> 0Untre | U40: =MID(K40,9,25) -> d Light CC Gas Oi
...

Sheet S-3
A2: Shell Deer Park Refining Company
A3: Sales to 3rd Party by Material
F4: S-3
A7: 40725
A8: Material No | B8: BBL Qty | C8: Amount
A9: 306 | B9: 99637.27 | C9: 14513142
A10: 351 | B10: 1128300.2 | C10: 1.3454812e+08
A11: 429 | B11: 39621 | C11: 4889398.4
A12: 646 | B12: 295368.33 | C12: 38425268
A13: 866 | B13: 1356647.1 | C13: 25870627
A14: 1046 | B14: 71199.554 | C14: 4443521.9
A15: 8048 | B15: 53008.19 | C15: 7050163.5
A16: 8199 | B16: 3.6379788e-12 | C16: 0
A17: 8708 | B17: 143473.4 | C17: 13847698
A18: 26672 | B18: 579117.75 | C18: 76008700
A19: 26797 | B19: 1020337.6 | C19: 1.2462647e+08
A20: 26858 | B20: 1325160.9 | C20: 1.5681945e+08
... A41: 87591 | B41: 11578.37 | C41: 1476739
B48: 0 | C48: 0
B53: =SUM(B9:B52) -> 12570959 | C53: =SUM(C9:C52) -> 1.300445e+09

Sheet P-3
A2: Shell Deer Park Refining Company
A3: 3rd Party Purchases Summary by Material
D4: P-3
A6: 40756
A7: Material No | B7: Qty BBL | C7: Amount
A8: 204 | B8: 325073.57 | C8: 29940577
A9: 280 | B9: 3454521.5 | C9: 3.3634636e+08
A10: 351 | B10: 175000 | C10: 21682500
A11: 863 | B11: 79543.858 | C11: 4360077.1
A12: 1048 | B12: 30999.257 | C12: 0
A13: 8162 | B13: 77791 | C13: 7679276.1
A14: 8720 | B14: 0 | C14: 34899.12
A15: 8949 | B15: 33327.448 | C15: 973347.7
A16: 26797 | B16: 100000 | C16: 12390000
A17: 41430 | B17: 500914.72 | C17: 55115972
A18: 50029 | B18: 996902 | C18: 1.2349722e+08
A19: 82396 | B19: 499886 | C19: 59319425
... A37: 50392 | B37: 0 | C37: 0
B47: =SUM(B8:B46) -> 8004960.6 | C47: =SUM(C8:C46) -> 8.4367698e+08

Sheet Validation
C1: SHARE Shipments Vs 3rd Party Sales | G1: SHARE Receipts Vs 3rd Party Purchases
A2: 000110 | B2: Ballast Water | C2: =SUMIF('Physical - BBLS'!J:J,A2,'Physical - BBLS'!E:E) -> 0 | D2: =SUMIF('S-3'!A:A,A2,'S-3'!B:B) -> 0 | E2: =+D2-C2 -> 0 | G2: =SUMIF('Physical - BBLS'!J:J,A2,'Physical - BBLS'!C:C) -> 0 | H2: =SUMIF('P-3'!A:A,A2,'P-3'!B:B) -> 0 | I2: =+H2-G2 -> 0
A3: 000130 | B3: JP-5 ANTIICANT | C3: =SUMIF('Physical - BBLS'!J:J,A3,'Physical - BBLS'!E:E) -> 0 | D3: =SUMIF('S-3'!A:A,A3,'S-3'!B:B) -> 0 | E3: =+D3-C3 -> 0 | G3: =SUMIF('Physical - BBLS'!J:J,A3,'Physical - BBLS'!C:C) -> 0 | H3: =SUMIF('P-3'!A:A,A3,'P-3'!B:B) -> 0 | I3: =+H3-G3 -> 0
A4: 000204 | B4: Napo | C4: =SUMIF('Physical - BBLS'!J:J,A4,'Physical - BBLS'!E:E) -> 0 | D4: =SUMIF('S-3'!A:A,A4,'S-3'!B:B) -> 0 | E4: =+D4-C4 -> 0 | G4: =SUMIF('Physical - BBLS'!J:J,A4,'Physical - BBLS'!C:C) -> 325074 | H4: =SUMIF('P-3'!A:A,A4,'P-3'!B:B) -> 325073.57 | I4: =+H4-G4 -> -0.43
A5: 000206 | B5: Hoops | C5: =SUMIF('Physical - BBLS'!J:J,A5,'Physical - BBLS'!E:E) -> 0 | D5: =SUMIF('S-3'!A:A,A5,'S-3'!B:B) -> 0 | E5: =+D5-C5 -> 0 | G5: =SUMIF('Physical - BBLS'!J:J,A5,'Physical - BBLS'!C:C) -> 199292 | H5: =SUMIF('P-3'!A:A,A5,'P-3'!B:B) -> 199291.59 | I5: =+H5-G5 -> -0.41
A6: 000215 | B6: Cold Lake Blend Crude (Ca | C6: =SUMIF('Physical - BBLS'!J:J,A6,'Physical - BBLS'!E:E) -> 0 | D6: =SUMIF('S-3'!A:A,A6,'S-3'!B:B) -> 0 | E6: =+D6-C6 -> 0 | G6: =SUMIF('Physical - BBLS'!J:J,A6,'Physical - BBLS'!C:C) -> 119656 | H6: =SUMIF('P-3'!A:A,A6,'P-3'!B:B) -> 119655.53 | I6: =+H6-G6 -> -0.47
A7: 000252 | B7: Mars Crude | C7: =SUMIF('Physical - BBLS'!J:J,A7,'Physical - BBLS'!E:E) -> 0 | D7: =SUMIF('S-3'!A:A,A7,'S-3'!B:B) -> 0 | E7: =+D7-C7 -> 0 | G7: =SUMIF('Physical - BBLS'!J:J,A7,'Physical - BBLS'!C:C) -> -154 | H7: =SUMIF('P-3'!A:A,A7,'P-3'!B:B) -> -153.66 | I7: =+H7-G7 -> 0.34
A8: 000280 | B8: Maya | C8: =SUMIF('Physical - BBLS'!J:J,A8,'Physical - BBLS'!E:E) -> 0 | D8: =SUMIF('S-3'!A:A,A8,'S-3'!B:B) -> 0 | E8: =+D8-C8 -> 0 | G8: =SUMIF('Physical - BBLS'!J:J,A8,'Physical - BBLS'!C:C) -> 6909043 | H8: =SUMIF('P-3'!A:A,A8,'P-3'!B:B) -> 3454521.5 | I8: =+H8-G8 -> -3454521.5 | J8: Pecten Invoice
A9: 000306 | B9: Toluene for gasoline blen | C9: =SUMIF('Physical - BBLS'!J:J,A9,'Physical - BBLS'!E:E) -> 99637 | D9: =SUMIF('S-3'!A:A,A9,'S-3'!B:B) -> 99637.27 | E9: =+D9-C9 -> 0.27 | G9: =SUMIF('Physical - BBLS'!J:J,A9,'Physical - BBLS'!C:C) -> 0 | H9: =SUMIF('P-3'!A:A,A9,'P-3'!B:B) -> 0 | I9: =+H9-G9 -> 0
A10: 000319 | B10: PUL 93 RVP 7/8# | C10: =SUMIF('Physical - BBLS'!J:J,A10,'Physical - BBLS'!E:E) -> 0 | D10: =SUMIF('S-3'!A:A,A10,'S-3'!B:B) -> 0 | E10: =+D10-C10 -> 0 | G10: =SUMIF('Physical - BBLS'!J:J,A10,'Physical - BBLS'!C:C) -> 0 | H10: =SUMIF('P-3'!A:A,A10,'P-3'!B:B) -> 0 | I10: =+H10-G10 -> 0
A11: 000351 | B11: RUL87 RVP 9.0 | C11: =SUMIF('Physical - BBLS'!J:J,A11,'Physical - BBLS'!E:E) -> 1128300 | D11: =SUMIF('S-3'!A:A,A11,'S-3'!B:B) -> 1128300.2 | E11: =+D11-C11 -> 0.24 | G11: =SUMIF('Physical - BBLS'!J:J,A11,'Physical - BBLS'!C:C) -> 175000 | H11: =SUMIF('P-3'!A:A,A11,'P-3'!B:B) -> 175000 | I11: =+H11-G11 -> 0
A12: 000402 | B12: JP-8 ANTIICANT | C12: =SUMIF('Physical - BBLS'!J:J,A12,'Physical - BBLS'!E:E) -> 0 | D12: =SUMIF('S-3'!A:A,A12,'S-3'!B:B) -> 0 | E12: =+D12-C12 -> 0 | G12: =SUMIF('Physical - BBLS'!J:J,A12,'Physical - BBLS'!C:C) -> 0 | H12: =SUMIF('P-3'!A:A,A12,'P-3'!B:B) -> 0 | I12: =+H12-G12 -> 0
A13: 000410 | B13: JET A | C13: =SUMIF('Physical - BBLS'!J:J,A13,'Physical - BBLS'!E:E) -> 103380 | D13: =SUMIF('S-3'!A:A,A13,'S-3'!B:B) -> 103379.93 | E13: =+D13-C13 -> -0.07 | G13: =SUMIF('Physical - BBLS'!J:J,A13,'Physical - BBLS'!C:C) -> 258562 | H13: =SUMIF('P-3'!A:A,A13,'P-3'!B:B) -> 258561.79 | I13: =+H13-G13 -> -0.21285714
A14: 000429 | B14: Low Sulfur Diesel | C14: =SUMIF('Physical - BBLS'!J:J,A14,'Physical - BBLS'!E:E) -> 39621 | D14: =SUMIF('S-3'!A:A,A14,'S-3'!B:B) -> 39621 | E14: =+D14-C14 -> 0 | G14: =SUMIF('Physical - BBLS'!J:J,A14,'Physical - BBLS'!C:C) -> 0 | H14: =SUMIF('P-3'!A:A,A14,'P-3'!B:B) -> 0 | I14: =+H14-G14 -> 0
A15: 000646 | B15: JP8 Turbine Fuel | C15: =SUMIF('Physical - BBLS'!J:J,A15,'Physical - BBLS'!E:E) -> 295368 | D15: =SUMIF('S-3'!A:A,A15,'S-3'!B:B) -> 295368.33 | E15: =+D15-C15 -> 0.33 | G15: =SUMIF('Physical - BBLS'!J:J,A15,'Physical - BBLS'!C:C) -> 0 | H15: =SUMIF('P-3'!A:A,A15,'P-3'!B:B) -> 0 | I15: =+H15-G15 -> 0
A16: 000804 | B16: Slop Oil | C16: =SUMIF('Physical - BBLS'!J:J,A16,'Physical - BBLS'!E:E) -> 0 | D16: =SUMIF('S-3'!A:A,A16,'S-3'!B:B) -> 0 | E16: =+D16-C16 -> 0 | G16: =SUMIF('Physical - BBLS'!J:J,A16,'Physical - BBLS'!C:C) -> 0 | H16: =SUMIF('P-3'!A:A,A16,'P-3'!B:B) -> 0 | I16: =+H16-G16 -> 0
A17: 000863 | B17: Purchased Hydrogen | C17: =SUMIF('Physical - BBLS'!J:J,A17,'Physical - BBLS'!E:E) -> 0 | D17: =SUMIF('S-3'!A:A,A17,'S-3'!B:B) -> 0 | E17: =+D17-C17 -> 0 | G17: =SUMIF('Physical - BBLS'!J:J,A17,'Physical - BBLS'!C:C) -> 79544 | H17: =SUMIF('P-3'!A:A,A17,'P-3'!B:B) -> 79543.858 | I17: =+H17-G17 -> -0.142
A18: 000866 | B18: Coke Offsite | C18: =SUMIF('Physical - BBLS'!J:J,A18,'Physical - BBLS'!E:E) -> 1356645 | D18: =SUMIF('S-3'!A:A,A18,'S-3'!B:B) -> 1356647.1 | E18: =+D18-C18 -> 2.0689569 | G18: =SUMIF('Physical - BBLS'!J:J,A18,'Physical - BBLS'!C:C) -> 0 | H18: =SUMIF('P-3'!A:A,A18,'P-3'!B:B) -> 0 | I18: =+H18-G18 -> 0
A19: 000896 | B19: Shell Marine Diesel Fuel | C19: =SUMIF('Physical - BBLS'!J:J,A19,'Physical - BBLS'!E:E) -> 0 | D19: =SUMIF('S-3'!A:A,A19,'S-3'!B:B) -> 0 | E19: =+D19-C19 -> 0 | G19: =SUMIF('Physical - BBLS'!J:J,A19,'Physical - BBLS'!C:C) -> 0 | H19: =SUMIF('P-3'!A:A,A19,'P-3'!B:B) -> 0 | I19: =+H19-G19 -> 0
A20: 000918 | B20: PLAT-2 Feed | C20: =SUMIF('Physical - BBLS'!J:J,A20,'Physical - BBLS'!E:E) -> 0 | D20: =SUMIF('S-3'!A:A,A20,'S-3'!B:B) -> 0 | E20: =+D20-C20 -> 0 | G20: =SUMIF('Physical - BBLS'!J:J,A20,'Physical - BBLS'!C:C) -> 0 | H20: =SUMIF('P-3'!A:A,A20,'P-3'!B:B) -> 0 | I20: =+H20-G20 -> 0
... A45: 008771 | B45: Untreated Heavy CC Gas Oi | C45: =SUMIF('Physical - BBLS'!J:J,A45,'Physical - BBLS'!E:E) -> 0 | D45: =SUMIF('S-3'!A:A,A45,'S-3'!B:B) -> 0 | E45: =+D45-C45 -> 0 | G45: =SUMIF('Physical - BBLS'!J:J,A45,'Physical - BBLS'!C:C) -> 0 | H45: =SUMIF('P-3'!A:A,A45,'P-3'!B:B) -> 0 | I45: =+H45-G45 -> 0
A46: 008949 | B46: Natural Gas-Hydro Feed Na | C46: =SUMIF('Physical - BBLS'!J:J,A46,'Physical - BBLS'!E:E) -> 0 | D46: =SUMIF('S-3'!A:A,A46,'S-3'!B:B) -> 0 | E46: =+D46-C46 -> 0 | G46: =SUMIF('Physical - BBLS'!J:J,A46,'Physical - BBLS'!C:C) -> 60071 | H46: =SUMIF('P-3'!A:A,A46,'P-3'!B:B) -> 33327.448 | I46: =+H46-G46 -> -26743.552 | J46: 8949 | K46: Routine monthly variance
A47: 008951 | B47: Refinery Fuel Gas | C47: =SUMIF('Physical - BBLS'!J:J,A47,'Physical - BBLS'!E:E) -> 0 | D47: =SUMIF('S-3'!A:A,A47,'S-3'!B:B) -> 0 | E47: =+D47-C47 -> 0 | G47: =SUMIF('Physical - BBLS'!J:J,A47,'Physical - BBLS'!C:C) -> 0 | H47: =SUMIF('P-3'!A:A,A47,'P-3'!B:B) -> 0 | I47: =+H47-G47 -> 0
A48: 024504 | B48: Untreated Kerosene | C48: =SUMIF('Physical - BBLS'!J:J,A48,'Physical - BBLS'!E:E) -> 0 | D48: =SUMIF('S-3'!A:A,A48,'S-3'!B:B) -> 0 | E48: =+D48-C48 -> 0 | G48: =SUMIF('Physical - BBLS'!J:J,A48,'Physical - BBLS'!C:C) -> 0 | H48: =SUMIF('P-3'!A:A,A48,'P-3'!B:B) -> 0 | I48: =+H48-G48 -> 0
A49: 026647 | B49: BG PUL 90 RVP>7.8 CONV ET | C49: =SUMIF('Physical - BBLS'!J:J,A49,'Physical - BBLS'!E:E) -> 0 | D49: =SUMIF('S-3'!A:A,A49,'S-3'!B:B) -> 0 | E49: =+D49-C49 -> 0 | G49: =SUMIF('Physical - BBLS'!J:J,A49,'Physical - BBLS'!C:C) -> 0 | H49: =SUMIF('P-3'!A:A,A49,'P-3'!B:B) -> 0 | I49: =+H49-G49 -> 0
A50: 026668 | B50: Winter RBOB - 10% Ethanol | C50: =SUMIF('Physical - BBLS'!J:J,A50,'Physical - BBLS'!E:E) -> 0 | D50: =SUMIF('S-3'!A:A,A50,'S-3'!B:B) -> 0 | E50: =+D50-C50 -> 0 | G50: =SUMIF('Physical - BBLS'!J:J,A50,'Physical - BBLS'!C:C) -> 0 | H50: =SUMIF('P-3'!A:A,A50,'P-3'!B:B) -> 0 | I50: =+H50-G50 -> 0
A51: 026672 | B51: Shell Turbine Fuel JP-5 | C51: =SUMIF('Physical - BBLS'!J:J,A51,'Physical - BBLS'!E:E) -> 579118 | D51: =SUMIF('S-3'!A:A,A51,'S-3'!B:B) -> 579117.75 | E51: =+D51-C51 -> -0.25 | G51: =SUMIF('Physical - BBLS'!J:J,A51,'Physical - BBLS'!C:C) -> 0 | H51: =SUMIF('P-3'!A:A,A51,'P-3'!B:B) -> 0 | I51: =+H51-G51 -> 0
A52: 026797 | B52: Summer RBOB - 10% Ethanol | C52: =SUMIF('Physical - BBLS'!J:J,A52,'Physical - BBLS'!E:E) -> 1020338 | D52: =SUMIF('S-3'!A:A,A52,'S-3'!B:B) -> 1020337.6 | E52: =+D52-C52 -> -0.4 | G52: =SUMIF('Physical - BBLS'!J:J,A52,'Physical - BBLS'!C:C) -> 100000 | H52: =SUMIF('P-3'!A:A,A52,'P-3'!B:B) -> 100000 | I52: =+H52-G52 -> 0
A53: 026858 | B53: PMI Gasoline | C53: =SUMIF('Physical - BBLS'!J:J,A53,'Physical - BBLS'!E:E) -> 1325161 | D53: =SUMIF('S-3'!A:A,A53,'S-3'!B:B) -> 1325160.9 | E53: =+D53-C53 -> -0.096 | G53: =SUMIF('Physical - BBLS'!J:J,A53,'Physical - BBLS'!C:C) -> 0 | H53: =SUMIF('P-3'!A:A,A53,'P-3'!B:B) -> 0 | I53: =+H53-G53 -> 0
A54: 027101 | B54: GN Ultra LS Diesel 2S-15 | C54: =SUMIF('Physical - BBLS'!J:J,A54,'Physical - BBLS'!E:E) -> 2635787 | D54: =SUMIF('S-3'!A:A,A54,'S-3'!B:B) -> 2635787 | E54: =+D54-C54 -> 0.04 | G54: =SUMIF('Physical - BBLS'!J:J,A54,'Physical - BBLS'!C:C) -> 0 | H54: =SUMIF('P-3'!A:A,A54,'P-3'!B:B) -> 0 | I54: =+H54-G54 -> 0
A55: 034201 | B55: Gas Blend Naphtha DPMC | C55: =SUMIF('Physical - BBLS'!J:J,A55,'Physical - BBLS'!E:E) -> 0 | D55: =SUMIF('S-3'!A:A,A55,'S-3'!B:B) -> 0 | E55: =+D55-C55 -> 0 | G55: =SUMIF('Physical - BBLS'!J:J,A55,'Physical - BBLS'!C:C) -> 0 | H55: =SUMIF('P-3'!A:A,A55,'P-3'!B:B) -> 0 | I55: =+H55-G55 -> 0
A56: 034203 | B56: Sales Naphtha | C56: =SUMIF('Physical - BBLS'!J:J,A56,'Physical - BBLS'!E:E) -> 56050 | D56: =SUMIF('S-3'!A:A,A56,'S-3'!B:B) -> 56049.75 | E56: =+D56-C56 -> -0.25 | G56: =SUMIF('Physical - BBLS'!J:J,A56,'Physical - BBLS'!C:C) -> 0 | H56: =SUMIF('P-3'!A:A,A56,'P-3'!B:B) -> 0 | I56: =+H56-G56 -> 0
A57: 034214 | B57: Pyrolysis Heavy Gasoline | C57: =SUMIF('Physical - BBLS'!J:J,A57,'Physical - BBLS'!E:E) -> 0 | D57: =SUMIF('S-3'!A:A,A57,'S-3'!B:B) -> 0 | E57: =+D57-C57 -> 0 | G57: =SUMIF('Physical - BBLS'!J:J,A57,'Physical - BBLS'!C:C) -> 0 | H57: =SUMIF('P-3'!A:A,A57,'P-3'!B:B) -> 0 | I57: =+H57-G57 -> 0
A58: 036515 | B58: Med Sulfur Cat Cracked Fe | C58: =SUMIF('Physical - BBLS'!J:J,A58,'Physical - BBLS'!E:E) -> 0 | D58: =SUMIF('S-3'!A:A,A58,'S-3'!B:B) -> 0 | E58: =+D58-C58 -> 0 | G58: =SUMIF('Physical - BBLS'!J:J,A58,'Physical - BBLS'!C:C) -> 0 | H58: =SUMIF('P-3'!A:A,A58,'P-3'!B:B) -> 0 | I58: =+H58-G58 -> 0
... A93: 092550 | B93: SH.PROP/PROPY-UNODOR | C93: =SUMIF('Physical - BBLS'!J:J,A93,'Physical - BBLS'!E:E) -> 167222 | D93: =SUMIF('S-3'!A:A,A93,'S-3'!B:B) -> 167221.6 | E93: =+D93-C93 -> -0.399 | G93: =SUMIF('Physical - BBLS'!J:J,A93,'Physical - BBLS'!C:C) -> 0 | H93: =SUMIF('P-3'!A:A,A93,'P-3'!B:B) -> 0 | I93: =+H93-G93 -> 0
C94: =SUMIF('Physical - BBLS'!J:J,A94,'Physical - BBLS'!E:E) -> 0 | D94: =SUMIF('S-3'!A:A,A94,'S-3'!B:B) -> 0 | E94: =+D94-C94 -> 0 | G94: =SUMIF('Physical - BBLS'!J:J,A94,'Physical - BBLS'!C:C) -> 0 | H94: =SUMIF('P-3'!A:A,A94,'P-3'!B:B) -> 0 | I94: =+H94-G94 -> 0
C95: =SUMIF('Physical - BBLS'!J:J,A95,'Physical - BBLS'!E:E) -> 0 | D95: =SUMIF('S-3'!A:A,A95,'S-3'!B:B) -> 0 | E95: =+D95-C95 -> 0 | G95: =SUMIF('Physical - BBLS'!J:J,A95,'Physical - BBLS'!C:C) -> 0 | H95: =SUMIF('P-3'!A:A,A95,'P-3'!B:B) -> 0 | I95: =+H95-G95 -> 0
C96: =SUMIF('Physical - BBLS'!J:J,A96,'Physical - BBLS'!E:E) -> 0 | D96: =SUMIF('S-3'!A:A,A96,'S-3'!B:B) -> 0 | E96: =+D96-C96 -> 0 | G96: =SUMIF('Physical - BBLS'!J:J,A96,'Physical - BBLS'!C:C) -> 0 | H96: =SUMIF('P-3'!A:A,A96,'P-3'!B:B) -> 0 | I96: =+H96-G96 -> 0
C97: =SUMIF('Physical - BBLS'!J:J,A97,'Physical - BBLS'!E:E) -> 0 | D97: =SUMIF('S-3'!A:A,A97,'S-3'!B:B) -> 0 | E97: =+D97-C97 -> 0 | G97: =SUMIF('Physical - BBLS'!J:J,A97,'Physical - BBLS'!C:C) -> 0 | H97: =SUMIF('P-3'!A:A,A97,'P-3'!B:B) -> 0 | I97: =+H97-G97 -> 0
C98: =SUMIF('Physical - BBLS'!J:J,A98,'Physical - BBLS'!E:E) -> 0 | D98: =SUMIF('S-3'!A:A,A98,'S-3'!B:B) -> 0 | E98: =+D98-C98 -> 0 | G98: =SUMIF('Physical - BBLS'!J:J,A98,'Physical - BBLS'!C:C) -> 0 | H98: =SUMIF('P-3'!A:A,A98,'P-3'!B:B) -> 0 | I98: =+H98-G98 -> 0
...

Sheet Carga
A1: 110 | B1: 2715.5 | C1: 0 | D1: -1894 | E1: 0 | F1: 0 | G1: 0 | H1: 822 | I1: Ballast Water | J1: 0
A2: 130 | B2: 1030.5 | C2: 0 | D2: -0.5 | E2: 0 | F2: 0 | G2: 0 | H2: 1030 | I2: JP-5 ANTIICANT | J2: 0
A3: 204 | B3: 0 | C3: 162537 | D3: -162537 | E3: 0 | F3: 0 | G3: 0 | H3: 0 | I3: Napo | J3: 0
A4: 206 | B4: 0 | C4: 99646 | D4: -86876 | E4: 0 | F4: 0 | G4: 0 | H4: 12769.5 | I4: Hoops | J4: 0
A5: 215 | B5: 57920 | C5: 59828 | D5: -48625.5 | E5: 0 | F5: 0 | G5: 0 | H5: 69122.5 | I5: Cold Lake Blend Crude (Ca | J5: 0
A6: 252 | B6: 89130.5 | C6: -77 | D6: -89053.5 | E6: 0 | F6: 0 | G6: 0 | H6: 0 | I6: Mars Crude | J6: 0
A7: 280 | B7: 765766.5 | C7: 3454521.5 | D7: -3441366 | E7: 0 | F7: 0 | G7: 1578 | H7: 777344 | I7: Maya | J7: 0
A8: 306 | B8: 7497 | C8: 0 | D8: 66250.5 | E8: 49818.5 | F8: 0 | G8: 128 | H8: 23800.5 | I8: Toluene for gasoline blen | J8: 0
A9: 319 | B9: 350 | C9: 0 | D9: 0 | E9: 0 | F9: 0 | G9: 0 | H9: 350 | I9: PUL 93 RVP 7/8# | J9: 0
A10: 351 | B10: 28670 | C10: 87500 | D10: 584016.5 | E10: 564150 | F10: 0 | G10: 955 | H10: 135081 | I10: RUL87 RVP 9.0 | J10: 0
A11: 402 | B11: 38.5 | C11: 0 | D11: 0 | E11: 0 | F11: 0 | G11: 0 | H11: 38.5 | I11: JP-8 ANTIICANT | J11: 0
A12: 410 | B12: 0 | C12: 129281 | D12: -77591 | E12: 51690 | F12: 0 | G12: 0 | H12: 0 | I12: JET A | J12: 0
... A93: 92606 | B93: 22257.5 | C93: 52609 | D93: -58494.5 | E93: 0 | F93: 0 | G93: 0 | H93: 16372.5 | I93: Isobutane | J93: 0
B95: =SUM(B1:B94) -> 4158279 | C95: =SUM(C1:C94) -> 5727615 | D95: =SUM(D1:D94) -> 401030.5 | E95: =SUM(E1:E94) -> 6316476 | F95: =SUM(F1:F94) -> 0 | G95: =SUM(G1:G94) -> 14307.5 | H95: =SUM(H1:H94) -> 3819530

Sheet Reporte
B1: Artículo | C1: Inv/Inicial | D1: Recepción | E1: Prod/Cons | F1: Embarques | G1: Cons. | H1: Perd/Gan. | I1: Inv/Final
B2: 1037 | C2: 0 | D2: 0 | E2: 38690 | F2: 0 | G2: 0 | H2: 0 | I2: 0
B4: 1046 | C4: 22714.5 | D4: 0 | E4: 42098 | F4: 35599 | G4: 0 | H4: 0 | I4: 29213.5
B6: 1048 | C6: 0 | D6: 0 | E6: 30999.5 | F6: 30999.5 | G6: 0 | H6: 0 | I6: 0
B8: 110 | C8: 2715.5 | D8: 0 | E8: -1894 | F8: 0 | G8: 0 | H8: 0 | I8: 822
B10: 130 | C10: 1030.5 | D10: 0 | E10: -0.5 | F10: 0 | G10: 0 | H10: 0 | I10: 1030
B12: 204 | C12: 0 | D12: 162537 | E12: -162537 | F12: 0 | G12: 0 | H12: 0 | I12: 0
B14: 206 | C14: 0 | D14: 99646 | E14: -86876 | F14: 0 | G14: 0 | H14: 0 | I14: 12769.5
B16: 215 | C16: 57920 | D16: 59828 | E16: -48625.5 | F16: 0 | G16: 0 | H16: 0 | I16: 69122.5
B18: 24504 | C18: 2441 | D18: 0 | E18: 12664 | F18: 0 | G18: 0 | H18: 0 | I18: 15105
B20: 252 | C20: 89130.5 | D20: -77 | E20: -89053.5 | F20: 0 | G20: 0 | H20: 0 | I20: 0
B22: 26647 | C22: 31654 | D22: 0 | E22: -25684 | F22: 0 | G22: 0 | H22: 0 | I22: 5970
B24: 26668 | C24: 0 | D24: 0 | E24: 15 | F24: 0 | G24: 0 | H24: 15 | I24: 0
... B186: 92606 | C186: 22257.5 | D186: 52609 | E186: -58494.5 | F186: 0 | G186: 0 | H186: 0 | I186: 16372.5
C188: =SUM(C2:C186) -> 4158279 | D188: =SUM(D2:D186) -> 5727615 | E188: =SUM(E2:E186) -> 401030.5 | F188: =SUM(F2:F186) -> 6316476 | G188: =SUM(G2:G186) -> 0 | H188: =SUM(H2:H186) -> 14307.5 | I188: =SUM(I2:I186) -> 3819530
C189: =+Carga!B95 -> 4158279 | D189: =+Carga!C95 -> 5727615 | E189: =+Carga!D95 -> 401030.5 | F189: =+Carga!E95 -> 6316476 | G189: =+Carga!F95 -> 0 | H189: =+Carga!G95 -> 14307.5 | I189: =+Carga!H95 -> 3819530
C190: =+C188-C189 -> 0 | D190: =+D188-D189 -> 0 | E190: =+E188-E189 -> 0 | F190: =+F188-F189 -> 0 | G190: =+G188-G189 -> 0 | H190: =+H188-H189 -> 0 | I190: =+I188-I189 -> 0
A205: >
